[2023-12-06T21:49:40.716+0500] {taskinstance.py:1159} INFO - Dependencies all met for dep_context=non-requeueable deps ti=<TaskInstance: etl_dag2.extract_data scheduled__2023-01-13T00:00:00+00:00 [queued]>
[2023-12-06T21:49:40.724+0500] {taskinstance.py:1159} INFO - Dependencies all met for dep_context=requeueable deps ti=<TaskInstance: etl_dag2.extract_data scheduled__2023-01-13T00:00:00+00:00 [queued]>
[2023-12-06T21:49:40.724+0500] {taskinstance.py:1361} INFO - Starting attempt 1 of 2
[2023-12-06T21:49:40.843+0500] {taskinstance.py:1382} INFO - Executing <Task(PythonOperator): extract_data> on 2023-01-13 00:00:00+00:00
[2023-12-06T21:49:40.845+0500] {standard_task_runner.py:57} INFO - Started process 8617 to run task
[2023-12-06T21:49:40.848+0500] {standard_task_runner.py:84} INFO - Running: ['airflow', 'tasks', 'run', 'etl_dag2', 'extract_data', 'scheduled__2023-01-13T00:00:00+00:00', '--job-id', '31', '--raw', '--subdir', 'DAGS_FOLDER/airflow_dag.py', '--cfg-path', '/tmp/tmp3xesptgy']
[2023-12-06T21:49:40.849+0500] {standard_task_runner.py:85} INFO - Job 31: Subtask extract_data
[2023-12-06T21:49:40.978+0500] {task_command.py:416} INFO - Running <TaskInstance: etl_dag2.extract_data scheduled__2023-01-13T00:00:00+00:00 [running]> on host amina-HP-ProBook-450-G2
[2023-12-06T21:49:41.198+0500] {taskinstance.py:1662} INFO - Exporting env vars: AIRFLOW_CTX_DAG_OWNER='amina_bibi' AIRFLOW_CTX_DAG_ID='etl_dag2' AIRFLOW_CTX_TASK_ID='extract_data' AIRFLOW_CTX_EXECUTION_DATE='2023-01-13T00:00:00+00:00' AIRFLOW_CTX_TRY_NUMBER='1' AIRFLOW_CTX_DAG_RUN_ID='scheduled__2023-01-13T00:00:00+00:00'
[2023-12-06T21:49:41.199+0500] {taskinstance.py:1937} ERROR - Task failed with exception
Traceback (most recent call last):
  File "/home/amina/miniconda/lib/python3.11/site-packages/airflow/operators/python.py", line 192, in execute
    return_value = self.execute_callable()
                   ^^^^^^^^^^^^^^^^^^^^^^^
  File "/home/amina/miniconda/lib/python3.11/site-packages/airflow/operators/python.py", line 209, in execute_callable
    return self.python_callable(*self.op_args, **self.op_kwargs)
           ^^^^^^^^^^^^^^^^^^^^^^^^^^^^^^^^^^^^^^^^^^^^^^^^^^^^^
  File "/home/amina/airflow/dags/airflow_dag.py", line 45, in extract_data
    with open(data_source_path, 'r') as file:
         ^^^^^^^^^^^^^^^^^^^^^^^^^^^
FileNotFoundError: [Errno 2] No such file or directory: '/home/amina/airflow/dags/data.csv'
[2023-12-06T21:49:41.206+0500] {taskinstance.py:1400} INFO - Marking task as UP_FOR_RETRY. dag_id=etl_dag2, task_id=extract_data, execution_date=20230113T000000, start_date=20231206T164940, end_date=20231206T164941
[2023-12-06T21:49:41.350+0500] {standard_task_runner.py:104} ERROR - Failed to execute job 31 for task extract_data ([Errno 2] No such file or directory: '/home/amina/airflow/dags/data.csv'; 8617)
[2023-12-06T21:49:41.381+0500] {local_task_job_runner.py:228} INFO - Task exited with return code 1
[2023-12-06T21:49:41.411+0500] {taskinstance.py:2778} INFO - 0 downstream tasks scheduled from follow-on schedule check
