[2023-12-06T23:13:43.228+0500] {taskinstance.py:1159} INFO - Dependencies all met for dep_context=non-requeueable deps ti=<TaskInstance: etl_dag2.transform_data scheduled__2023-04-09T00:00:00+00:00 [queued]>
[2023-12-06T23:13:43.236+0500] {taskinstance.py:1159} INFO - Dependencies all met for dep_context=requeueable deps ti=<TaskInstance: etl_dag2.transform_data scheduled__2023-04-09T00:00:00+00:00 [queued]>
[2023-12-06T23:13:43.237+0500] {taskinstance.py:1361} INFO - Starting attempt 2 of 2
[2023-12-06T23:13:43.418+0500] {taskinstance.py:1382} INFO - Executing <Task(PythonOperator): transform_data> on 2023-04-09 00:00:00+00:00
[2023-12-06T23:13:43.422+0500] {standard_task_runner.py:57} INFO - Started process 28366 to run task
[2023-12-06T23:13:43.426+0500] {standard_task_runner.py:84} INFO - Running: ['airflow', 'tasks', 'run', 'etl_dag2', 'transform_data', 'scheduled__2023-04-09T00:00:00+00:00', '--job-id', '387', '--raw', '--subdir', 'DAGS_FOLDER/airflow_dag.py', '--cfg-path', '/tmp/tmplvxqy7i0']
[2023-12-06T23:13:43.426+0500] {standard_task_runner.py:85} INFO - Job 387: Subtask transform_data
[2023-12-06T23:13:43.603+0500] {task_command.py:416} INFO - Running <TaskInstance: etl_dag2.transform_data scheduled__2023-04-09T00:00:00+00:00 [running]> on host amina-HP-ProBook-450-G2
[2023-12-06T23:13:43.793+0500] {taskinstance.py:1662} INFO - Exporting env vars: AIRFLOW_CTX_DAG_OWNER='amina_bibi' AIRFLOW_CTX_DAG_ID='etl_dag2' AIRFLOW_CTX_TASK_ID='transform_data' AIRFLOW_CTX_EXECUTION_DATE='2023-04-09T00:00:00+00:00' AIRFLOW_CTX_TRY_NUMBER='2' AIRFLOW_CTX_DAG_RUN_ID='scheduled__2023-04-09T00:00:00+00:00'
[2023-12-06T23:13:43.795+0500] {taskinstance.py:1937} ERROR - Task failed with exception
Traceback (most recent call last):
  File "/home/amina/miniconda/lib/python3.11/site-packages/airflow/operators/python.py", line 192, in execute
    return_value = self.execute_callable()
                   ^^^^^^^^^^^^^^^^^^^^^^^
  File "/home/amina/miniconda/lib/python3.11/site-packages/airflow/operators/python.py", line 209, in execute_callable
    return self.python_callable(*self.op_args, **self.op_kwargs)
           ^^^^^^^^^^^^^^^^^^^^^^^^^^^^^^^^^^^^^^^^^^^^^^^^^^^^^
TypeError: transform_data() missing 1 required positional argument: 'data'
[2023-12-06T23:13:43.802+0500] {taskinstance.py:1400} INFO - Marking task as FAILED. dag_id=etl_dag2, task_id=transform_data, execution_date=20230409T000000, start_date=20231206T181343, end_date=20231206T181343
[2023-12-06T23:13:44.065+0500] {standard_task_runner.py:104} ERROR - Failed to execute job 387 for task transform_data (transform_data() missing 1 required positional argument: 'data'; 28366)
[2023-12-06T23:13:44.079+0500] {local_task_job_runner.py:228} INFO - Task exited with return code 1
[2023-12-06T23:13:44.100+0500] {taskinstance.py:2778} INFO - 0 downstream tasks scheduled from follow-on schedule check
