[2023-12-06T22:00:40.979+0500] {taskinstance.py:1159} INFO - Dependencies all met for dep_context=non-requeueable deps ti=<TaskInstance: etl_dag2.extract_data scheduled__2023-01-21T00:00:00+00:00 [queued]>
[2023-12-06T22:00:40.990+0500] {taskinstance.py:1159} INFO - Dependencies all met for dep_context=requeueable deps ti=<TaskInstance: etl_dag2.extract_data scheduled__2023-01-21T00:00:00+00:00 [queued]>
[2023-12-06T22:00:40.990+0500] {taskinstance.py:1361} INFO - Starting attempt 2 of 2
[2023-12-06T22:00:41.656+0500] {taskinstance.py:1382} INFO - Executing <Task(PythonOperator): extract_data> on 2023-01-21 00:00:00+00:00
[2023-12-06T22:00:41.659+0500] {standard_task_runner.py:57} INFO - Started process 20888 to run task
[2023-12-06T22:00:41.664+0500] {standard_task_runner.py:84} INFO - Running: ['airflow', 'tasks', 'run', 'etl_dag2', 'extract_data', 'scheduled__2023-01-21T00:00:00+00:00', '--job-id', '95', '--raw', '--subdir', 'DAGS_FOLDER/airflow_dag.py', '--cfg-path', '/tmp/tmppuxli8vz']
[2023-12-06T22:00:41.665+0500] {standard_task_runner.py:85} INFO - Job 95: Subtask extract_data
[2023-12-06T22:00:42.337+0500] {task_command.py:416} INFO - Running <TaskInstance: etl_dag2.extract_data scheduled__2023-01-21T00:00:00+00:00 [running]> on host amina-HP-ProBook-450-G2
[2023-12-06T22:00:43.132+0500] {taskinstance.py:1662} INFO - Exporting env vars: AIRFLOW_CTX_DAG_OWNER='amina_bibi' AIRFLOW_CTX_DAG_ID='etl_dag2' AIRFLOW_CTX_TASK_ID='extract_data' AIRFLOW_CTX_EXECUTION_DATE='2023-01-21T00:00:00+00:00' AIRFLOW_CTX_TRY_NUMBER='2' AIRFLOW_CTX_DAG_RUN_ID='scheduled__2023-01-21T00:00:00+00:00'
[2023-12-06T22:00:43.134+0500] {taskinstance.py:1937} ERROR - Task failed with exception
Traceback (most recent call last):
  File "/home/amina/miniconda/lib/python3.11/site-packages/airflow/operators/python.py", line 192, in execute
    return_value = self.execute_callable()
                   ^^^^^^^^^^^^^^^^^^^^^^^
  File "/home/amina/miniconda/lib/python3.11/site-packages/airflow/operators/python.py", line 209, in execute_callable
    return self.python_callable(*self.op_args, **self.op_kwargs)
           ^^^^^^^^^^^^^^^^^^^^^^^^^^^^^^^^^^^^^^^^^^^^^^^^^^^^^
  File "/home/amina/airflow/dags/airflow_dag.py", line 45, in extract_data
    with open(data_source_path, 'r') as file:
         ^^^^^^^^^^^^^^^^^^^^^^^^^^^
FileNotFoundError: [Errno 2] No such file or directory: '/home/amina/airflow/dags/data.csv'
[2023-12-06T22:00:43.144+0500] {taskinstance.py:1400} INFO - Marking task as FAILED. dag_id=etl_dag2, task_id=extract_data, execution_date=20230121T000000, start_date=20231206T170040, end_date=20231206T170043
[2023-12-06T22:00:43.476+0500] {standard_task_runner.py:104} ERROR - Failed to execute job 95 for task extract_data ([Errno 2] No such file or directory: '/home/amina/airflow/dags/data.csv'; 20888)
[2023-12-06T22:00:43.521+0500] {local_task_job_runner.py:228} INFO - Task exited with return code 1
[2023-12-06T22:00:43.551+0500] {taskinstance.py:2778} INFO - 0 downstream tasks scheduled from follow-on schedule check
