[2023-12-15T22:20:14.123+0500] {taskinstance.py:1159} INFO - Dependencies all met for dep_context=non-requeueable deps ti=<TaskInstance: etl_dag2.load_data_to_github manual__2023-12-15T17:14:45.972015+00:00 [queued]>
[2023-12-15T22:20:14.138+0500] {taskinstance.py:1159} INFO - Dependencies all met for dep_context=requeueable deps ti=<TaskInstance: etl_dag2.load_data_to_github manual__2023-12-15T17:14:45.972015+00:00 [queued]>
[2023-12-15T22:20:14.139+0500] {taskinstance.py:1361} INFO - Starting attempt 2 of 2
[2023-12-15T22:20:14.490+0500] {taskinstance.py:1382} INFO - Executing <Task(PythonOperator): load_data_to_github> on 2023-12-15 17:14:45.972015+00:00
[2023-12-15T22:20:14.495+0500] {standard_task_runner.py:57} INFO - Started process 10077 to run task
[2023-12-15T22:20:14.503+0500] {standard_task_runner.py:84} INFO - Running: ['airflow', 'tasks', 'run', 'etl_dag2', 'load_data_to_github', 'manual__2023-12-15T17:14:45.972015+00:00', '--job-id', '1351', '--raw', '--subdir', 'DAGS_FOLDER/airflow_dag.py', '--cfg-path', '/tmp/tmp3bd6nxyw']
[2023-12-15T22:20:14.504+0500] {standard_task_runner.py:85} INFO - Job 1351: Subtask load_data_to_github
[2023-12-15T22:20:14.736+0500] {task_command.py:416} INFO - Running <TaskInstance: etl_dag2.load_data_to_github manual__2023-12-15T17:14:45.972015+00:00 [running]> on host amina-HP-ProBook-450-G2
[2023-12-15T22:20:15.001+0500] {taskinstance.py:1662} INFO - Exporting env vars: AIRFLOW_CTX_DAG_OWNER='amina_bibi' AIRFLOW_CTX_DAG_ID='etl_dag2' AIRFLOW_CTX_TASK_ID='load_data_to_github' AIRFLOW_CTX_EXECUTION_DATE='2023-12-15T17:14:45.972015+00:00' AIRFLOW_CTX_TRY_NUMBER='2' AIRFLOW_CTX_DAG_RUN_ID='manual__2023-12-15T17:14:45.972015+00:00'
[2023-12-15T22:20:15.002+0500] {taskinstance.py:1937} ERROR - Task failed with exception
Traceback (most recent call last):
  File "/home/amina/miniconda/lib/python3.11/site-packages/airflow/operators/python.py", line 192, in execute
    return_value = self.execute_callable()
                   ^^^^^^^^^^^^^^^^^^^^^^^
  File "/home/amina/miniconda/lib/python3.11/site-packages/airflow/operators/python.py", line 209, in execute_callable
    return self.python_callable(*self.op_args, **self.op_kwargs)
           ^^^^^^^^^^^^^^^^^^^^^^^^^^^^^^^^^^^^^^^^^^^^^^^^^^^^^
TypeError: load_data_to_github() missing 1 required positional argument: 'transformed_data'
[2023-12-15T22:20:15.008+0500] {taskinstance.py:1400} INFO - Marking task as FAILED. dag_id=etl_dag2, task_id=load_data_to_github, execution_date=20231215T171445, start_date=20231215T172014, end_date=20231215T172015
[2023-12-15T22:20:15.274+0500] {standard_task_runner.py:104} ERROR - Failed to execute job 1351 for task load_data_to_github (load_data_to_github() missing 1 required positional argument: 'transformed_data'; 10077)
[2023-12-15T22:20:15.316+0500] {local_task_job_runner.py:228} INFO - Task exited with return code 1
[2023-12-15T22:20:15.333+0500] {taskinstance.py:2778} INFO - 0 downstream tasks scheduled from follow-on schedule check
